Workbook

Sheet Monthly Data 2024
C1: Billing | K1: Charging | S1: Overall
A2: Month | B2: Monetization KPI | C2: Total Number of Assets Download - Billing | D2: Total Number of Assets Reused with Savings - Billing | E2: Pending Feedback - Billing | F2: Asset Savings - Billing | G2: Automation Savings - Billing | H2: Total Savings - Billing | I2: Billability Hours - Billing | J2: Billing Savings % | K2: Total Number of Assets Download - Charging | L2: Total Number of Assets Reused with Savings - Charging | M2: Pending Feedback - Charging | N2: Asset Savings - Charging | O2: Automation Savings - Charging | P2: Total Savings - Charging | Q2: Billability Hours - Charging | R2: Charging Savings | S2: Total Savings - Monetization | T2: Billability Hours - Monetization | U2: Monetization Savings %
A3: Jan | B3: 0.156 | C3: 44 | D3: 14 | E3: 28 | F3: 147.02 | G3: 0 | H3: =Table24[[#This Row],[Asset Savings - Billing]]+Table24[[#This Row],[Automation Savings - Billing]] | I3: 10667 | J3: =H3/I3 | K3: 378 | L3: 123 | M3: 193 | N3: 2758.05 | O3: 2201 | P3: =SUM(Table24[[#This Row],[Asset Savings - Charging]]+Table24[[#This Row],[Automation Savings - Charging]]) | Q3: 54796 | R3: =P3/Q3 | S3: =P3+H3 | T3: =I3+Q3 | U3: =S3/T3
A4: Feb | B4: 0.156 | C4: 25 | D4: 5 | E4: 14 | F4: 202 | G4: 0.8 | H4: =Table24[[#This Row],[Asset Savings - Billing]]+Table24[[#This Row],[Automation Savings - Billing]] | I4: 8705 | J4: =H4/I4 | K4: 473 | L4: 290 | M4: 47 | N4: 4514.5 | O4: 4231.86 | P4: 9004 | Q4: 51348 | R4: =P4/Q4 | S4: =P4+H4 | T4: =I4+Q4 | U4: =S4/T4
A5: Mar | B5: 0.156 | C5: 16 | D5: 3 | E5: 5 | F5: =70-18 | G5: 0 | H5: =Table24[[#This Row],[Asset Savings - Billing]]+Table24[[#This Row],[Automation Savings - Billing]] | I5: 8515.25 | J5: =H5/I5 | K5: 401 | L5: 216 | M5: 106 | N5: 3416.43 | O5: 5168 | P5: =SUM(Table24[[#This Row],[Asset Savings - Charging]]+Table24[[#This Row],[Automation Savings - Charging]]) | Q5: 50460.78 | R5: =P5/Q5 | S5: =P5+H5 | T5: =I5+Q5 | U5: =S5/T5
A6: April | B6: 0.156 | C6: 19 | D6: 6 | E6: 5 | F6: 452 | G6: 750.5 | H6: =Table24[[#This Row],[Asset Savings - Billing]]+Table24[[#This Row],[Automation Savings - Billing]] | I6: 9092.05 | J6: =H6/I6 | K6: 444 | L6: 282 | M6: 165 | N6: 4221.91 | O6: 5639.37 | P6: =SUM(Table24[[#This Row],[Asset Savings - Charging]]+Table24[[#This Row],[Automation Savings - Charging]]) | Q6: 52768.98 | R6: =P6/Q6 | S6: =P6+H6 | T6: =I6+Q6 | U6: =S6/T6
A7: May | B7: 0.156 | C7: 28 | D7: 11 | E7: 5 | F7: 708.32 | G7: 202 | H7: =Table24[[#This Row],[Asset Savings - Billing]]+Table24[[#This Row],[Automation Savings - Billing]] | I7: 9998 | J7: =H7/I7 | K7: 394 | L7: 247 | M7: 125 | N7: 3647.89 | O7: 8652.99 | P7: =SUM(Table24[[#This Row],[Asset Savings - Charging]]+Table24[[#This Row],[Automation Savings - Charging]]) | Q7: 54648 | R7: =P7/Q7 | S7: =P7+H7 | T7: =I7+Q7 | U7: =S7/T7
A8: Jun | B8: 0.156 | C8: 22 | D8: 7 | E8: 1 | F8: 687 | G8: 38 | H8: =Table24[[#This Row],[Asset Savings - Billing]]+Table24[[#This Row],[Automation Savings - Billing]] | I8: 9858 | J8: =H8/I8 | K8: 368 | L8: 253 | M8: 120 | N8: 3633 | O8: 3813 | P8: =SUM(Table24[[#This Row],[Asset Savings - Charging]]+Table24[[#This Row],[Automation Savings - Charging]]) | Q8: 49661 | R8: =P8/Q8 | S8: =P8+H8 | T8: =I8+Q8 | U8: =S8/T8
A9: Jul | B9: 0.156 | C9: 17 | D9: 8 | E9: 4 | F9: 327 | G9: 665.45 | H9: =SUM(Table24[[#This Row],[Asset Savings - Billing]:[Automation Savings - Billing]]) | I9: 12327.62 | J9: =H9/I9 | K9: 424 | L9: 226 | M9: 41 | N9: 2915.54 | O9: 3942.04 | P9: =SUM(Table24[[#This Row],[Asset Savings - Charging]]+Table24[[#This Row],[Automation Savings - Charging]]) | Q9: 52333 | R9: =P9/Q9 | S9: =P9+H9 | T9: =I9+Q9 | U9: =S9/T9
A10: Aug | B10: 0.156 | C10: 25 | D10: 12 | E10: 3 | F10: 597.5 | G10: 14 | H10: =SUM(Table24[[#This Row],[Asset Savings - Billing]:[Automation Savings - Billing]]) | I10: 8960 | J10: =H10/I10 | K10: 299 | L10: 210 | M10: 52 | N10: 2622.4 | O10: 5126.5 | P10: =SUM(Table24[[#This Row],[Asset Savings - Charging]]+Table24[[#This Row],[Automation Savings - Charging]]) | Q10: 44748 | R10: =P10/Q10 | S10: =P10+H10 | T10: =I10+Q10 | U10: =S10/T10
A11: Sep | B11: 0.156 | C11: 30 | D11: 10 | E11: 4 | F11: 833.1 | G11: 230 | H11: =SUM(Table24[[#This Row],[Asset Savings - Billing]:[Automation Savings - Billing]]) | I11: 9265.85 | J11: =H11/I11 | K11: 205 | L11: 214 | M11: 34 | N11: 1965.36 | O11: 3738.5 | P11: =SUM(Table24[[#This Row],[Asset Savings - Charging]]+Table24[[#This Row],[Automation Savings - Charging]]) | Q11: 46314.13 | R11: =P11/Q11 | S11: =P11+H11 | T11: =I11+Q11 | U11: =S11/T11
A12: Oct | B12: 0.156 | C12: 10 | D12: 7 | E12: 3 | F12: 0.8 | G12: 564 | H12: =SUM(Table24[[#This Row],[Asset Savings - Billing]:[Automation Savings - Billing]]) | I12: 8979 | J12: =H12/I12 | K12: 389 | L12: 261 | M12: 80 | N12: 3300.88 | O12: 3156 | P12: =SUM(Table24[[#This Row],[Asset Savings - Charging]]+Table24[[#This Row],[Automation Savings - Charging]]) | Q12: 48080 | R12: =P12/Q12 | S12: =P12+H12 | T12: =I12+Q12 | U12: =S12/T12
A13: Nov | B13: 0.156 | C13: 4 | D13: 1 | E13: 3 | F13: 12 | G13: 0 | H13: =SUM(Table24[[#This Row],[Asset Savings - Billing]:[Automation Savings - Billing]]) | I13: 9343.25 | J13: =H13/I13 | K13: 346 | L13: 215 | M13: 73 | N13: 2945.39 | O13: 4144 | P13: =SUM(Table24[[#This Row],[Asset Savings - Charging]]+Table24[[#This Row],[Automation Savings - Charging]]) | Q13: 43363 | R13: =P13/Q13 | S13: =P13+H13 | T13: =I13+Q13 | U13: =S13/T13
A14: Dec | B14: 0.156 | C14: 15 | D14: 10 | E14: 3 | F14: 364.55 | G14: 6 | H14: =SUM(Table24[[#This Row],[Asset Savings - Billing]:[Automation Savings - Billing]]) | I14: 9590.5 | J14: =H14/I14 | K14: 395 | L14: 186 | M14: 85 | N14: 3131.6 | O14: 2816 | P14: 7590 | Q14: 35712 | R14: =P14/Q14 | S14: =P14+H14 | T14: =I14+Q14 | U14: =S14/T14
A15: YTD | B15: 0.156 | C15: =SUM(C3:C14) | D15: =SUM(D3:D14) | E15: =E14 | F15: =SUM(F3:F14) | G15: =SUM(G3:G14) | H15: =SUM(H3:H14) | I15: =SUM(I3:I14) | J15: =H15/I15 | K15: =SUM(K3:K14) | L15: =SUM(L3:L14) | M15: =M14 | N15: =SUM(N3:N14) | O15: =SUM(O3:O14) | P15: =SUM(P3:P14) | Q15: =SUM(Q3:Q14) | R15: =P15/Q15 | S15: =P15+H15 | T15: =I15+Q15 | U15: =S15/T15

Sheet Monthly Data 2025
C1: Billing | K1: Charging | S1: Overall
A2: Month | B2: Monetization KPI | C2: Total Number of Assets Download - Billing | D2: Total Number of Assets Reused with Savings - Billing | E2: Pending Feedback - Billing | F2: Asset Savings - Billing | G2: Automation Savings - Billing | H2: Total Savings - Billing | I2: Billability Hours - Billing | J2: Billing Savings % | K2: Total Number of Assets Download - Charging | L2: Total Number of Assets Reused with Savings - Charging | M2: Pending Feedback - Charging | N2: Asset Savings - Charging | O2: Automation Savings - Charging | P2: Total Savings - Charging | Q2: Billability Hours - Charging | R2: Charging Savings | S2: Total Savings - Monetization | T2: Billability Hours - Monetization | U2: Monetization Savings %
A3: Jan | B3: 0.16 | C3: 20 | D3: 4 | E3: 8 | F3: 143 | G3: 48.1 | H3: =Table2[[#This Row],[Asset Savings - Billing]]+Table2[[#This Row],[Automation Savings - Billing]] | I3: 6651.85 | J3: =H3/I3 | K3: 285 | L3: 141 | M3: 49 | N3: 1551.24 | O3: 2684 | P3: =Table2[[#This Row],[Asset Savings - Charging]]+Table2[[#This Row],[Automation Savings - Charging]] | Q3: 44613 | R3: =Table2[[#This Row],[Total Savings - Charging]]/Table2[[#This Row],[Billability Hours - Charging]] | S3: =Table2[[#This Row],[Total Savings - Billing]]+Table2[[#This Row],[Total Savings - Charging]] | T3: =Table2[[#This Row],[Billability Hours - Billing]]+Table2[[#This Row],[Billability Hours - Charging]] | U3: =S3/T3
A4: Feb | B4: 0.16 | C4: 20 | D4: 5 | E4: 8 | F4: 112 | G4: 24.5 | H4: =Table2[[#This Row],[Asset Savings - Billing]]+Table2[[#This Row],[Automation Savings - Billing]] | I4: 6033 | J4: =H4/I4 | K4: 213 | L4: 239 | M4: 44 | N4: 2465 | O4: 3455 | P4: =Table2[[#This Row],[Asset Savings - Charging]]+Table2[[#This Row],[Automation Savings - Charging]] | Q4: 41659 | R4: =Table2[[#This Row],[Total Savings - Charging]]/Table2[[#This Row],[Billability Hours - Charging]] | S4: =Table2[[#This Row],[Total Savings - Billing]]+Table2[[#This Row],[Total Savings - Charging]] | T4: =Table2[[#This Row],[Billability Hours - Billing]]+Table2[[#This Row],[Billability Hours - Charging]] | U4: =S4/T4
A5: Mar | B5: 0.16 | C5: 9 | D5: 4 | E5: 7 | F5: 148 | G5: 0.8 | H5: =Table2[[#This Row],[Asset Savings - Billing]]+Table2[[#This Row],[Automation Savings - Billing]] | I5: 6090 | J5: =H5/I5 | K5: 223 | L5: 139 | M5: 62 | N5: 969.48 | O5: 2723.24 | P5: =Table2[[#This Row],[Asset Savings - Charging]]+Table2[[#This Row],[Automation Savings - Charging]] | Q5: 40996 | R5: =Table2[[#This Row],[Total Savings - Charging]]/Table2[[#This Row],[Billability Hours - Charging]] | S5: =Table2[[#This Row],[Total Savings - Billing]]+Table2[[#This Row],[Total Savings - Charging]] | T5: =Table2[[#This Row],[Billability Hours - Billing]]+Table2[[#This Row],[Billability Hours - Charging]] | U5: =S5/T5
A6: April | B6: 0.16 | C6: 20 | D6: 10 | E6: 6 | F6: 684.42 | G6: 0.45 | H6: =Table2[[#This Row],[Asset Savings - Billing]]+Table2[[#This Row],[Automation Savings - Billing]] | I6: 6217 | J6: =H6/I6 | K6: 258 | L6: 233 | M6: 139 | N6: 2183.55 | O6: 4112 | P6: =Table2[[#This Row],[Asset Savings - Charging]]+Table2[[#This Row],[Automation Savings - Charging]] | Q6: 40248 | R6: =Table2[[#This Row],[Total Savings - Charging]]/Table2[[#This Row],[Billability Hours - Charging]] | S6: =Table2[[#This Row],[Total Savings - Billing]]+Table2[[#This Row],[Total Savings - Charging]] | T6: =Table2[[#This Row],[Billability Hours - Billing]]+Table2[[#This Row],[Billability Hours - Charging]] | U6: =S6/T6
A7: May | B7: 0.16 | C7: 29 | D7: 10 | E7: 3 | F7: 254.9 | G7: 19.65 | H7: =Table2[[#This Row],[Asset Savings - Billing]]+Table2[[#This Row],[Automation Savings - Billing]] | I7: 6908 | J7: =H7/I7 | K7: 355 | L7: 221 | M7: 67 | N7: 1785.6 | O7: 4764.8 | P7: =Table2[[#This Row],[Asset Savings - Charging]]+Table2[[#This Row],[Automation Savings - Charging]] | Q7: 43121 | R7: =Table2[[#This Row],[Total Savings - Charging]]/Table2[[#This Row],[Billability Hours - Charging]] | S7: =Table2[[#This Row],[Total Savings - Billing]]+Table2[[#This Row],[Total Savings - Charging]] | T7: =Table2[[#This Row],[Billability Hours - Billing]]+Table2[[#This Row],[Billability Hours - Charging]] | U7: =S7/T7
A8: Jun | B8: 0.16 | C8: 22 | D8: 7 | E8: 13 | F8: 131.2 | G8: 5.45 | H8: =Table2[[#This Row],[Asset Savings - Billing]]+Table2[[#This Row],[Automation Savings - Billing]] | I8: 7306 | J8: =H8/I8 | K8: 277 | L8: 134 | M8: 58 | N8: 1613.72 | O8: 3734.9 | P8: =Table2[[#This Row],[Asset Savings - Charging]]+Table2[[#This Row],[Automation Savings - Charging]] | Q8: 40965 | R8: =Table2[[#This Row],[Total Savings - Charging]]/Table2[[#This Row],[Billability Hours - Charging]] | S8: =Table2[[#This Row],[Total Savings - Billing]]+Table2[[#This Row],[Total Savings - Charging]] | T8: =Table2[[#This Row],[Billability Hours - Billing]]+Table2[[#This Row],[Billability Hours - Charging]] | U8: =S8/T8
A9: Jul | B9: 0.16 | C9: 34 | D9: 6 | E9: 3 | F9: 502.2 | G9: 22.1 | H9: =Table2[[#This Row],[Asset Savings - Billing]]+Table2[[#This Row],[Automation Savings - Billing]] | I9: 10082 | J9: =H9/I9 | K9: 309 | L9: 210 | M9: 73 | N9: 1797.23 | O9: 3669.84 | P9: =Table2[[#This Row],[Asset Savings - Charging]]+Table2[[#This Row],[Automation Savings - Charging]] | Q9: 43825 | R9: =Table2[[#This Row],[Total Savings - Charging]]/Table2[[#This Row],[Billability Hours - Charging]] | S9: =Table2[[#This Row],[Total Savings - Billing]]+Table2[[#This Row],[Total Savings - Charging]] | T9: =Table2[[#This Row],[Billability Hours - Billing]]+Table2[[#This Row],[Billability Hours - Charging]] | U9: =S9/T9
A10: Aug | B10: 0.16 | C10: 17 | D10: 10 | E10: 28 | F10: 26.3 | G10: 326.49 | H10: =Table2[[#This Row],[Asset Savings - Billing]]+Table2[[#This Row],[Automation Savings - Billing]] | I10: 8841 | J10: =H10/I10 | K10: 229 | L10: 148 | M10: 92 | N10: 1535.1 | O10: 2105.07 | P10: =Table2[[#This Row],[Asset Savings - Charging]]+Table2[[#This Row],[Automation Savings - Charging]] | Q10: 39175 | R10: =Table2[[#This Row],[Total Savings - Charging]]/Table2[[#This Row],[Billability Hours - Charging]] | S10: =Table2[[#This Row],[Total Savings - Billing]]+Table2[[#This Row],[Total Savings - Charging]] | T10: =Table2[[#This Row],[Billability Hours - Billing]]+Table2[[#This Row],[Billability Hours - Charging]] | U10: =S10/T10
A11: Sep | B11: 0.16 | C11: 8 | D11: 5 | E11: 31 | F11: 379.5 | G11: 14.4 | H11: =Table2[[#This Row],[Asset Savings - Billing]]+Table2[[#This Row],[Automation Savings - Billing]] | I11: 9505 | J11: =H11/I11 | K11: 153 | L11: 95 | M11: 140 | N11: 1564.68 | O11: 699.29 | P11: =Table2[[#This Row],[Asset Savings - Charging]]+Table2[[#This Row],[Automation Savings - Charging]] | Q11: 40576 | R11: =Table2[[#This Row],[Total Savings - Charging]]/Table2[[#This Row],[Billability Hours - Charging]] | S11: =Table2[[#This Row],[Total Savings - Billing]]+Table2[[#This Row],[Total Savings - Charging]] | T11: =Table2[[#This Row],[Billability Hours - Billing]]+Table2[[#This Row],[Billability Hours - Charging]] | U11: =S11/T11
A12: Oct | B12: 0.16 | C12: 39 | D12: 6 | E12: 46 | F12: 212 | G12: 0.5 | H12: =Table2[[#This Row],[Asset Savings - Billing]]+Table2[[#This Row],[Automation Savings - Billing]] | I12: 8976 | J12: =H12/I12 | K12: 99 | L12: 52 | M12: 187 | N12: 784.4 | O12: 1058.77 | P12: 1843.17 | Q12: 39390 | R12: =Table2[[#This Row],[Total Savings - Charging]]/Table2[[#This Row],[Billability Hours - Charging]] | S12: =Table2[[#This Row],[Total Savings - Billing]]+Table2[[#This Row],[Total Savings - Charging]] | T12: =Table2[[#This Row],[Billability Hours - Billing]]+Table2[[#This Row],[Billability Hours - Charging]] | U12: =S12/T12
A13: Nov | B13: 0.16 | C13: 27 | D13: 19 | E13: 49 | F13: 289 | G13: 1064 | H13: =Table2[[#This Row],[Asset Savings - Billing]]+Table2[[#This Row],[Automation Savings - Billing]] | I13: 6541 | J13: =H13/I13 | K13: 96 | L13: 64 | M13: 193 | N13: 1375 | O13: 704 | P13: 2080 | Q13: 41298 | R13: =Table2[[#This Row],[Total Savings - Charging]]/Table2[[#This Row],[Billability Hours - Charging]] | S13: =Table2[[#This Row],[Total Savings - Billing]]+Table2[[#This Row],[Total Savings - Charging]] | T13: =Table2[[#This Row],[Billability Hours - Billing]]+Table2[[#This Row],[Billability Hours - Charging]] | U13: =S13/T13
A14: Dec | B14: 0.16 | C14: 31 | D14: 22 | E14: 52 | F14: 1901 | G14: 1144 | H14: =Table2[[#This Row],[Asset Savings - Billing]]+Table2[[#This Row],[Automation Savings - Billing]] | I14: 8606 | J14: =H14/I14 | K14: 193 | L14: 153 | M14: 221 | N14: 2602 | O14: 1882 | P14: 4486 | Q14: 29642 | R14: =Table2[[#This Row],[Total Savings - Charging]]/Table2[[#This Row],[Billability Hours - Charging]] | S14: =Table2[[#This Row],[Total Savings - Billing]]+Table2[[#This Row],[Total Savings - Charging]] | T14: =Table2[[#This Row],[Billability Hours - Billing]]+Table2[[#This Row],[Billability Hours - Charging]] | U14: =S14/T14
A15: YTD | B15: 0.16 | C15: =SUM(C3:C14) | D15: =SUM(D3:D14) | E15: =E3 | F15: =SUM(F3:F14) | G15: =SUM(G3:G14) | H15: =SUM(H3:H14) | I15: =SUM(I3:I14) | J15: =H15/I15 | K15: =SUM(K3:K14) | L15: =SUM(L3:L14) | M15: =M8 | N15: =SUM(N3:N14) | O15: =SUM(O3:O14) | P15: =SUM(P3:P14) | Q15: =SUM(Q3:Q14) | R15: =P15/Q15 | S15: =P15+H15 | T15: =I15+Q15 | U15: =S15/T15

Sheet Monthly Data 2026
C1: Billing | K1: Charging | S1: SDC CS&DFE | AA1: SDC Billing&MW | AI1: Overall
A2: Month | B2: Monetization KPI | C2: Total Number of Assets Download - Billing | D2: Total Number of Assets Reused with Savings - Billing | E2: Pending Feedback - Billing | F2: Asset Savings - Billing | G2: Automation Savings - Billing | H2: Total Savings - Billing | I2: Billability Hours - Billing | J2: Billing Savings % | K2: Total Number of Assets Download - Charging | L2: Total Number of Assets Reused with Savings - Charging | M2: Pending Feedback - Charging | N2: Asset Savings - Charging | O2: Automation Savings - Charging | P2: Total Savings - Charging | Q2: Billability Hours - Charging | R2: Charging Savings % | S2: Total Number of Assets Download - SDC CS&DFE | T2: Total Number of Assets Reused with Savings - SDC CS&DFE | U2: Pending Feedback - SDC CS&DFE | V2: Asset Savings - SDC CS&DFE | W2: Automation Savings - SDC CS&DFE | X2: Total Savings - SDC CS&DFE | Y2: Billability Hours - SDC CS&DFE | Z2: SDC CS&DFE Savings % | AA2: Total Number of Assets Download - SDC Billing&MW | AB2: Total Number of Assets Reused with Savings - SDC Billing&MW | AC2: Pending Feedback - SDC Billing&MW | AD2: Asset Savings - SDC Billing&MW | AE2: Automation Savings - SDC Billing&MW | AF2: Total Savings - SDC Billing&MW | AG2: Billability Hours - SDC Billing&MW | AH2: SDC Billing&MW Savings % | AI2: Total Savings - Monetization | AJ2: Billability Hours - Monetization | AK2: Monetization Savings %
A3: Jan | B3: 0.16 | C3: 4 | D3: 2 | F3: 0 | G3: 58.38 | H3: =Table25[[#This Row],[Asset Savings - Billing]]+Table25[[#This Row],[Automation Savings - Billing]] | I3: 9640.75 | J3: =H3/I3 | K3: 69 | L3: 67 | N3: 3080.7 | O3: 1080.35 | P3: =Table25[[#This Row],[Asset Savings - Charging]]+Table25[[#This Row],[Automation Savings - Charging]] | Q3: 36869 | R3: =Table25[[#This Row],[Total Savings - Charging]]/Table25[[#This Row],[Billability Hours - Charging]] | S3: 3 | T3: 4 | V3: 0 | W3: 1476 | X3: =Table25[[#This Row],[Asset Savings - SDC CS&DFE]]+Table25[[#This Row],[Automation Savings - SDC CS&DFE]] | Y3: 18045 | Z3: =Table25[[#This Row],[Total Savings - SDC CS&DFE]]/Table25[[#This Row],[Billability Hours - SDC CS&DFE]] | AA3: 0 | AB3: 0 | AD3: 0 | AE3: 0 | AF3: =Table25[[#This Row],[Asset Savings - SDC Billing&MW]]+Table25[[#This Row],[Automation Savings - SDC Billing&MW]] | AG3: 8010.64 | AH3: =Table25[[#This Row],[Total Savings - SDC Billing&MW]]/Table25[[#This Row],[Billability Hours - SDC Billing&MW]] | AI3: =Table25[[#This Row],[Total Savings - Billing]]+Table25[[#This Row],[Total Savings - Charging]]+Table25[[#This Row],[Total Savings - SDC CS&DFE]]+Table25[[#This Row],[Total Savings - SDC Billing&MW]] | AJ3: =Table25[[#This Row],[Billability Hours - Billing]]+Table25[[#This Row],[Billability Hours - Charging]]+Table25[[#This Row],[Billability Hours - SDC CS&DFE]]+Table25[[#This Row],[Billability Hours - SDC Billing&MW]] | AK3: =AI3/AJ3
A4: Feb | B4: 0.16 | C4: 17 | D4: 17 | F4: 307.5 | G4: 1071.6 | H4: =Table25[[#This Row],[Asset Savings - Billing]]+Table25[[#This Row],[Automation Savings - Billing]] | I4: 10714 | J4: =H4/I4 | L4: 46 | N4: 343.21 | O4: 689.5 | P4: =Table25[[#This Row],[Asset Savings - Charging]]+Table25[[#This Row],[Automation Savings - Charging]] | Q4: 39906 | R4: =Table25[[#This Row],[Total Savings - Charging]]/Table25[[#This Row],[Billability Hours - Charging]] | T4: 4 | V4: 2044 | W4: 300 | X4: =Table25[[#This Row],[Asset Savings - SDC CS&DFE]]+Table25[[#This Row],[Automation Savings - SDC CS&DFE]] | Y4: 19394 | Z4: =Table25[[#This Row],[Total Savings - SDC CS&DFE]]/Table25[[#This Row],[Billability Hours - SDC CS&DFE]] | AB4: 4 | AE4: 195.4 | AF4: =Table25[[#This Row],[Asset Savings - SDC Billing&MW]]+Table25[[#This Row],[Automation Savings - SDC Billing&MW]] | AG4: 9214.2 | AH4: =Table25[[#This Row],[Total Savings - SDC Billing&MW]]/Table25[[#This Row],[Billability Hours - SDC Billing&MW]] | AI4: =Table25[[#This Row],[Total Savings - Billing]]+Table25[[#This Row],[Total Savings - Charging]]+Table25[[#This Row],[Total Savings - SDC CS&DFE]]+Table25[[#This Row],[Total Savings - SDC Billing&MW]] | AJ4: =Table25[[#This Row],[Billability Hours - Billing]]+Table25[[#This Row],[Billability Hours - Charging]]+Table25[[#This Row],[Billability Hours - SDC CS&DFE]]+Table25[[#This Row],[Billability Hours - SDC Billing&MW]] | AK4: =AI4/AJ4
A5: Mar | B5: 0.16 | D5: 15 | F5: 183 | G5: 1038 | H5: =Table25[[#This Row],[Asset Savings - Billing]]+Table25[[#This Row],[Automation Savings - Billing]] | I5: 11854 | J5: =H5/I5 | L5: 103 | N5: 1476.81 | O5: 1610.45 | P5: =Table25[[#This Row],[Asset Savings - Charging]]+Table25[[#This Row],[Automation Savings - Charging]] | Q5: 44428 | R5: =Table25[[#This Row],[Total Savings - Charging]]/Table25[[#This Row],[Billability Hours - Charging]] | T5: 4 | W5: 5366 | X5: =Table25[[#This Row],[Asset Savings - SDC CS&DFE]]+Table25[[#This Row],[Automation Savings - SDC CS&DFE]] | Y5: 21191 | Z5: =Table25[[#This Row],[Total Savings - SDC CS&DFE]]/Table25[[#This Row],[Billability Hours - SDC CS&DFE]] | AB5: 8 | AD5: 3161 | AE5: 165 | AF5: =Table25[[#This Row],[Asset Savings - SDC Billing&MW]]+Table25[[#This Row],[Automation Savings - SDC Billing&MW]] | AG5: 9261.7 | AH5: =Table25[[#This Row],[Total Savings - SDC Billing&MW]]/Table25[[#This Row],[Billability Hours - SDC Billing&MW]] | AI5: =Table25[[#This Row],[Total Savings - Billing]]+Table25[[#This Row],[Total Savings - Charging]]+Table25[[#This Row],[Total Savings - SDC CS&DFE]]+Table25[[#This Row],[Total Savings - SDC Billing&MW]] | AJ5: =Table25[[#This Row],[Billability Hours - Billing]]+Table25[[#This Row],[Billability Hours - Charging]]+Table25[[#This Row],[Billability Hours - SDC CS&DFE]]+Table25[[#This Row],[Billability Hours - SDC Billing&MW]] | AK5: =AI5/AJ5
A6: April | B6: 0.16 | C6: 43 | D6: 17 | E6: 20 | F6: 819 | G6: 2981.05 | H6: =Table25[[#This Row],[Asset Savings - Billing]]+Table25[[#This Row],[Automation Savings - Billing]] | I6: 8837.75 | J6: =H6/I6 | K6: 154 | L6: 109 | M6: 73 | N6: 1000.83 | O6: 1322.16 | P6: =Table25[[#This Row],[Asset Savings - Charging]]+Table25[[#This Row],[Automation Savings - Charging]] | Q6: 34778.39 | R6: =Table25[[#This Row],[Total Savings - Charging]]/Table25[[#This Row],[Billability Hours - Charging]] | S6: 6 | T6: 3 | U6: 12 | V6: 816 | W6: 984 | X6: =Table25[[#This Row],[Asset Savings - SDC CS&DFE]]+Table25[[#This Row],[Automation Savings - SDC CS&DFE]] | Y6: 18041.4 | Z6: =Table25[[#This Row],[Total Savings - SDC CS&DFE]]/Table25[[#This Row],[Billability Hours - SDC CS&DFE]] | AA6: 2 | AB6: 2 | AC6: 2 | AD6: 0 | AE6: 90.4 | AF6: =Table25[[#This Row],[Asset Savings - SDC Billing&MW]]+Table25[[#This Row],[Automation Savings - SDC Billing&MW]] | AG6: 8151.65 | AH6: =Table25[[#This Row],[Total Savings - SDC Billing&MW]]/Table25[[#This Row],[Billability Hours - SDC Billing&MW]] | AI6: =Table25[[#This Row],[Total Savings - Billing]]+Table25[[#This Row],[Total Savings - Charging]]+Table25[[#This Row],[Total Savings - SDC CS&DFE]]+Table25[[#This Row],[Total Savings - SDC Billing&MW]] | AJ6: =Table25[[#This Row],[Billability Hours - Billing]]+Table25[[#This Row],[Billability Hours - Charging]]+Table25[[#This Row],[Billability Hours - SDC CS&DFE]]+Table25[[#This Row],[Billability Hours - SDC Billing&MW]] | AK6: =AI6/AJ6
A7: May | B7: 0.16 | P7: =Table25[[#This Row],[Asset Savings - Charging]]+Table25[[#This Row],[Automation Savings - Charging]] | X7: =Table25[[#This Row],[Asset Savings - SDC CS&DFE]]+Table25[[#This Row],[Automation Savings - SDC CS&DFE]] | AI7: =Table25[[#This Row],[Total Savings - Billing]]+Table25[[#This Row],[Total Savings - Charging]]+Table25[[#This Row],[Total Savings - SDC CS&DFE]]+Table25[[#This Row],[Total Savings - SDC Billing&MW]] | AJ7: =Table25[[#This Row],[Billability Hours - Billing]]+Table25[[#This Row],[Billability Hours - Charging]]+Table25[[#This Row],[Billability Hours - SDC CS&DFE]]+Table25[[#This Row],[Billability Hours - SDC Billing&MW]] | AK7: =AI7/AJ7
A8: Jun | B8: 0.16 | P8: =Table25[[#This Row],[Asset Savings - Charging]]+Table25[[#This Row],[Automation Savings - Charging]] | X8: =Table25[[#This Row],[Asset Savings - SDC CS&DFE]]+Table25[[#This Row],[Automation Savings - SDC CS&DFE]] | AI8: =Table25[[#This Row],[Total Savings - Billing]]+Table25[[#This Row],[Total Savings - Charging]]+Table25[[#This Row],[Total Savings - SDC CS&DFE]]+Table25[[#This Row],[Total Savings - SDC Billing&MW]] | AJ8: =Table25[[#This Row],[Billability Hours - Billing]]+Table25[[#This Row],[Billability Hours - Charging]]+Table25[[#This Row],[Billability Hours - SDC CS&DFE]]+Table25[[#This Row],[Billability Hours - SDC Billing&MW]] | AK8: =AI8/AJ8
A9: Jul | B9: 0.16 | P9: =Table25[[#This Row],[Asset Savings - Charging]]+Table25[[#This Row],[Automation Savings - Charging]] | X9: =Table25[[#This Row],[Asset Savings - SDC CS&DFE]]+Table25[[#This Row],[Automation Savings - SDC CS&DFE]] | AI9: =Table25[[#This Row],[Total Savings - Billing]]+Table25[[#This Row],[Total Savings - Charging]]+Table25[[#This Row],[Total Savings - SDC CS&DFE]]+Table25[[#This Row],[Total Savings - SDC Billing&MW]] | AJ9: =Table25[[#This Row],[Billability Hours - Billing]]+Table25[[#This Row],[Billability Hours - Charging]]+Table25[[#This Row],[Billability Hours - SDC CS&DFE]]+Table25[[#This Row],[Billability Hours - SDC Billing&MW]] | AK9: =AI9/AJ9
A10: Aug | B10: 0.16 | P10: =Table25[[#This Row],[Asset Savings - Charging]]+Table25[[#This Row],[Automation Savings - Charging]] | X10: =Table25[[#This Row],[Asset Savings - SDC CS&DFE]]+Table25[[#This Row],[Automation Savings - SDC CS&DFE]] | AI10: =Table25[[#This Row],[Total Savings - Billing]]+Table25[[#This Row],[Total Savings - Charging]]+Table25[[#This Row],[Total Savings - SDC CS&DFE]]+Table25[[#This Row],[Total Savings - SDC Billing&MW]] | AJ10: =Table25[[#This Row],[Billability Hours - Billing]]+Table25[[#This Row],[Billability Hours - Charging]]+Table25[[#This Row],[Billability Hours - SDC CS&DFE]]+Table25[[#This Row],[Billability Hours - SDC Billing&MW]] | AK10: =AI10/AJ10
A11: Sep | B11: 0.16 | P11: =Table25[[#This Row],[Asset Savings - Charging]]+Table25[[#This Row],[Automation Savings - Charging]] | X11: =Table25[[#This Row],[Asset Savings - SDC CS&DFE]]+Table25[[#This Row],[Automation Savings - SDC CS&DFE]] | AI11: =Table25[[#This Row],[Total Savings - Billing]]+Table25[[#This Row],[Total Savings - Charging]]+Table25[[#This Row],[Total Savings - SDC CS&DFE]]+Table25[[#This Row],[Total Savings - SDC Billing&MW]] | AJ11: =Table25[[#This Row],[Billability Hours - Billing]]+Table25[[#This Row],[Billability Hours - Charging]]+Table25[[#This Row],[Billability Hours - SDC CS&DFE]]+Table25[[#This Row],[Billability Hours - SDC Billing&MW]] | AK11: =AI11/AJ11
A12: Oct | B12: 0.16 | P12: =Table25[[#This Row],[Asset Savings - Charging]]+Table25[[#This Row],[Automation Savings - Charging]] | X12: =Table25[[#This Row],[Asset Savings - SDC CS&DFE]]+Table25[[#This Row],[Automation Savings - SDC CS&DFE]] | AI12: =Table25[[#This Row],[Total Savings - Billing]]+Table25[[#This Row],[Total Savings - Charging]]+Table25[[#This Row],[Total Savings - SDC CS&DFE]]+Table25[[#This Row],[Total Savings - SDC Billing&MW]] | AJ12: =Table25[[#This Row],[Billability Hours - Billing]]+Table25[[#This Row],[Billability Hours - Charging]]+Table25[[#This Row],[Billability Hours - SDC CS&DFE]]+Table25[[#This Row],[Billability Hours - SDC Billing&MW]] | AK12: =AI12/AJ12
A13: Nov | B13: 0.16 | P13: =Table25[[#This Row],[Asset Savings - Charging]]+Table25[[#This Row],[Automation Savings - Charging]] | X13: =Table25[[#This Row],[Asset Savings - SDC CS&DFE]]+Table25[[#This Row],[Automation Savings - SDC CS&DFE]] | AI13: =Table25[[#This Row],[Total Savings - Billing]]+Table25[[#This Row],[Total Savings - Charging]]+Table25[[#This Row],[Total Savings - SDC CS&DFE]]+Table25[[#This Row],[Total Savings - SDC Billing&MW]] | AJ13: =Table25[[#This Row],[Billability Hours - Billing]]+Table25[[#This Row],[Billability Hours - Charging]]+Table25[[#This Row],[Billability Hours - SDC CS&DFE]]+Table25[[#This Row],[Billability Hours - SDC Billing&MW]] | AK13: =AI13/AJ13
A14: Dec | B14: 0.16 | P14: =Table25[[#This Row],[Asset Savings - Charging]]+Table25[[#This Row],[Automation Savings - Charging]] | X14: =Table25[[#This Row],[Asset Savings - SDC CS&DFE]]+Table25[[#This Row],[Automation Savings - SDC CS&DFE]] | AI14: =Table25[[#This Row],[Total Savings - Billing]]+Table25[[#This Row],[Total Savings - Charging]]+Table25[[#This Row],[Total Savings - SDC CS&DFE]]+Table25[[#This Row],[Total Savings - SDC Billing&MW]] | AJ14: =Table25[[#This Row],[Billability Hours - Billing]]+Table25[[#This Row],[Billability Hours - Charging]]+Table25[[#This Row],[Billability Hours - SDC CS&DFE]]+Table25[[#This Row],[Billability Hours - SDC Billing&MW]] | AK14: =AI14/AJ14
A15: YTD | B15: 0.16 | C15: =SUM(C3:C14) | D15: =SUM(D3:D14) | E15: =E6 | F15: =SUM(F3:F14) | G15: =SUM(G3:G14) | H15: =SUM(H3:H14) | I15: =SUM(I3:I14) | J15: =H15/I15 | K15: =SUM(K3:K14) | L15: =SUM(L3:L14) | M15: =M6 | N15: =SUM(N3:N14) | O15: =SUM(O3:O14) | P15: =SUM(P3:P14) | Q15: =SUM(Q3:Q14) | R15: =P15/Q15 | S15: =SUM(S3:S14) | T15: =SUM(T3:T14) | U15: =U6 | V15: =SUM(V3:V14) | W15: =SUM(W3:W14) | X15: =SUM(X3:X14) | Y15: =SUM(Y3:Y14) | Z15: =X15/Y15 | AA15: =SUM(AA3:AA14) | AB15: =SUM(AB3:AB14) | AC15: =AC8 | AD15: =SUM(AD3:AD14) | AE15: =SUM(AE3:AE14) | AF15: =SUM(AF3:AF14) | AG15: =SUM(AG3:AG14) | AH15: =AF15/AG15 | AI15: =SUM(AI3:AI14) | AJ15: =SUM(AJ3:AJ14) | AK15: =AI15/AJ15

Sheet Star Awards 2026
A1: Name | B1: LM | C1: Domain
A2: Vivek Singh H | B2: Umesh Kumar Hasija | C2: SDC CS&DFE | D2: Jan
A3: Ujwala Gorksha Bankar | B3: Shishir Deshpande | C3: Billing | D3: Jan
A4: Rajni Priyanka Toppo | B4: Suman Chakraborty | C4: Billing | D4: Jan
A5: Arindam Maity | B5: Kamalbhai Bharatkumar Shah | C5: Charging | D5: Jan
A6: Partheeban R | B6: Bishnu Prasad Tripathy | C6: Charging | D6: Jan
A7: Shaik Razzaq | B7: Bishnu Prasad Tripathy | C7: Charging | D7: Jan
A8: Dinesh Kumar M K | B8: Amrit Das D | C8: Charging | D8: Jan
A9: Vasanth Francis | B9: Sasikumar Kesavan | C9: Charging | D9: Jan
A10: Udayakumar S | C10: Charging | D10: Feb
A11: Sudhanshu B Dubey | C11: Charging | D11: Feb
A12: Yaser Majeed | C12: Charging | D12: Feb
A13: Amit Kumar QQ | C13: Charging | D13: Feb
A14: Ateesh Varun | C14: Charging | D14: Feb
A15: Shilpi Srivastava | C15: SDC CS&DFE | D15: Feb
A16: Akbar Hussain | C16: SDC CS&DFE | D16: Feb
A17: Suparba Roy Mahapatra | C17: Billing | D17: Feb
A18: Badal Chandra Das | C18: Billing | D18: Feb
A19: N Sudarvanna Pillai | C19: Billing | D19: Feb
A20: Thota Arun Kumar | C20: Billing | D20: Feb
A21: Prashant Kumar Gupta K | C21: Billing | D21: Feb
... A41: Anshu Jaiswal | C41: SDC CS&DFE | D41: Mar

Sheet Top 5 and Assets
A1: Top 5 assets Charging | B1: Hours | E1: Top 5 asset Billing | F1: Hours
A2: Row Labels | B2: Sum of Total Saving | E2: Row Labels
A3: BSS - EC21 - SDP Report in Single Click - Script | B3: 13874.57 | E3: Weblogic Stop-Start Automation for Prepaid Magenta | F3: 1800
A4: BSS - EC21 - AIR Single Click Report - Script | B4: 3230.89 | E4: BSCS Regression Test Suite | F4: 650
A5: SDP Upgrade Customization (CDD-PSP & L1-PSP) | B5: 2950 | E5: BSCS_START/STOP APPLICATION AUTOMATION | F5: 551
A6: BSS - Ericsson Charging Automation framework Offering [ECAF Assets] Load Balancing - Tool | B6: 2767.72 | E6: BSS - EB - Deployment guide | F6: 532.4
A7: cECC TestAutomation ESSVT Asset for SDP Functional_Asset | B7: 2220 | E7: BSS - EB - Infra Deployment pipeline | F7: 514.5
A8: BSS - Ericsson Charging Automation framework Offering [ECAF Assets] SDP Upgrade[BM & VM] FNI - Tool | B8: 1390.8

Sheet Unused Assets
A1: CHARGING
A2: Asset Id | B2: Asset Name | C2: Node Type | D2: Asset Group
A3: 3631 | B3: BSS - CS16 - Extraction of Live Structures from SDP AIR RMA configuration - Tool | C3: CS - Multi Node | D3: 29~Business Configuration
A4: 51429 | B4: BSS - EC20 - SDP Business Config Time Based action use case - TOL | C4: SDP | D4: 29~Business Configuration
A5: 51870 | B5: BSS - EC20 - BC Automation - Tool | C5: CS - Multi Node | D5: 29~Business Configuration
A6: 52203 | B6: BSS - Charging system Automation framework Offering [ECAF Assets] NGVS Installation Bare Metal SNI - Tool | C6: NGVS | D6: 26~Installation
A7: 52222 | B7: BSS - Charging system Automation framework Offering [CSAF Assets] NGVS Integration FNI - Tool | C7: NGVS | D7: 26~Installation
A8: 52224 | B8: BSS - Charging system Automation framework Offering [CSAF Assets] AIR Integration SNI - Tool | C8: AIR | D8: 26~Installation
A9: 53326 | B9: BSS - CS - SDP AIR UTIL TOOL - SCRIPT | C9: CS - Multi Node | D9: 32~Miscellaneous
A10: 53754 | B10: BSS - CS Template Based Business Configuration | C10: CS - Multi Node | D10: 29~Business Configuration
A11: 54064 | B11: BSS-CS-license ordering Flow-FLOW | C11: CS | D11: 32~Miscellaneous
A12: 54159 | B12: BSS-CS18.1 - Traffic Simulator - Package | C12: CS - Multi Node | D12: 32~Miscellaneous
A13: 54539 | B13: BSS-EC20-Define/Update Business Configuration resources(Offer/DA/UA/UC/UT)in SDP SMA-Script | C13: SDP | D13: 29~Business Configuration
A14: 55799 | B14: BSS-EC20-NGVS ICP20-01 Upgrade Learnings | C14: NGVS | D14: 27~Upgrade
... A46: 72807 | B46: BSS - EC22.6 - Estimator for New Deployments – Tool | C46: CS - Multi Node | D46: 26~Installation
A47: 73012 | B47: BSS-EC22-CAF-AF Integration-MOP | D47: 26~Installation
A48: 73013 | B48: BSS-EC22-vCAF-SDP Diameter Integration -MOP | D48: 26~Installation
A49: 73321 | B49: BSS-EC22-Manual AIR Health Check | C49: AIR | D49: 32~Miscellaneous
A50: 73334 | B50: BSS - EC21 - OCC Health check - MOP | C50: OCC | D50: 32~Miscellaneous
A51: 73369 | B51: BSS - EC - Manual CCN Health Check_for_BM,VM | C51: CCN | D51: 32~Miscellaneous
A52: 73371 | B52: BSS - EC22 - OCC - Remote Syslog Server Integration | C52: OCC | D52: 32~Miscellaneous
A53: 73385 | B53: BSS - SWDP E2E Pipeline cEC Node-SDP Install and post healthcheck using CDD | C53: SDP | D53: 26~Installation
A54: 73504 | B54: BSS - EC 22.x - NGCRS Firmware Upgrade MOP | C54: NGCRS | D54: 27~Upgrade
A55: 73589 | B55: BSS - EC22-ECPCS-cAF-Verification-Solution-Document | C55: ECPCS | D55: 32~Miscellaneous
A56: 73591 | B56: BSS - EC22-ECPCS-cAIR-Verification-Solution-Document | C56: ECPCS | D56: 32~Miscellaneous
A57: 73592 | B57: BSS - EC22-ECPCS-cBCD-Verification-Solution-Document | C57: ECPCS | D57: 32~Miscellaneous
A58: 73593 | B58: BSS - EC22-ECPCS-cSDP-Verification-Solution-Document | C58: ECPCS | D58: 32~Miscellaneous
A59: 74176 | B59: BSS - EC22 - OCC O&M IP Change Procedure Guide | C59: OCC | D59: 32~Miscellaneous
A60: 74379 | B60: BOS-GDS-DEPLOYMENT-MOP | C60: GDS | D60: 32~Miscellaneous
... A68: 56184 | B68: BSS - EC20 - Virtual OCC Deployment Model Change Distributed to Non Distributed model - MOP | C68: OCC | D68: 26~Installation
A69: 57300 | B69: BSS - Ericsson Charging Automation framework Offering [ECAF HC Assets] ECMS HealthCheck - Tool | D69: 32~Miscellaneous
A70: 58474 | B70: BSS - EC20 - Feature Activation Impact Analysis & Implementation procedure - NIR | C70: CS - Multi Node | D70: 26~Installation
A71: 59433 | B71: BSS - EC20 - ECMS NFNT Test Object List | D71: 32~Miscellaneous
A72: 59434 | B72: BSS - EC20 - NGVS NFNT Test Object List | C72: NGVS | D72: 32~Miscellaneous
A73: 59435 | B73: BSS - EC20 - SDP NFNT Test Object List | D73: 32~Miscellaneous
A74: 59437 | B74: BSS - EC20 - OCC NFNT Distributed Test Object List | D74: 32~Miscellaneous
A75: 59448 | B75: BSS - EC20 - IVR - ICP version - Upgrade MOP for BM | C75: IVR | D75: 27~Upgrade
A76: 59450 | B76: BSS - EC20 - VXML IVR Customer Questionnare | C76: VXML | D76: 33~Migration Assets
A77: 59966 | B77: BSS-EC20-NGCRS-Disabling of Unused Network Interfaces | C77: NGCRS | D77: 32~Miscellaneous
A78: 60235 | B78: BSS - EC20 - NGVS User Acceptance Testing | C78: NGVS | D78: 32~Miscellaneous
...

Sheet Bottom Assets
A1: Asset Id | B1: Asset Name | E1: Asset Id | F1: Asset Name
A2: 55159 | B2: BSS - Ericsson Charging Automation framework Offering [ECAF Assets] CCN CBA ( Vmware) Installation Virtual SNI -Tool | E2: 77624 | F2: EEA 4 - Spotfire AutoRefresh Data Guide
A3: 52210 | B3: BSS - Ericsson Charging Automation framework Offering [ECAF Assets] OCC Installation Virtual SNI -Tool | E3: 72576 | F3: Automation for EOC & ECM Dormancy MOP execution
A4: 54562 | B4: BSS - EC20 - Feature Activation Impact Analysis - NIR | E4: 78438 | F4: DB Partitions Expiry Check
A5: 73862 | B5: BSS - CSS Healtcheck Connections for HC scripts | E5: 69658 | F5: EOC-ECM Data Cleanup Automation For Prepaid Magenta
A6: 62397 | B6: BSS - EC22 - Estimator Upgrade - Tool | E6: 69599 | F6: FCT Cleanup Automation Tool
A7: 75013 | B7: MOP Adding MSC (GT) in CCN | E7: 71820 | F7: Spectrum SSL Cert Renewal - Automation
A8: 52201 | B8: BSS - Ericsson Charging Automation framework Offering [ECAF Assets] AIR Installation Bare Metal SNI- Tool | E8: 71821 | F8: Vertex SSL Cert Renewal - Automation
A9: 63478 | B9: CCN CBA Scheduled BRM Backup | E9: 72193 | F9: BSS - EB23 - Testing - Ericsson Billing Automation Tool with ESSVT
A10: 52160 | B10: BSS - EC20 - SDP VoLTE & VoWIFI SDP BC - LLD | E10: 73383 | F10: BSS - EB - DMF Upgrade Automation - Tool
A11: 55807 | B11: BSS - EC20.1 - ECMS_SOLARIS TO LINUX MIGRATION - MOP | E11: 72244 | F11: Geocodeupdater_Tool_Automation
A12: 56268 | B12: BSS - Ericsson Charging Automation framework Offering [ECAF HC Assets] OCC HealthCheck - Tool | E12: 72243 | F12: SNMP Installation and Platform Upgradation
A13: 1303 | B13: BSS - CS18 - CCN Upgrade Network Impact Report - Impact Analysis | E13: 79945 | F13: Automation of AWS EC2 Instance Start Stop
A14: 71033 | B14: BSS - EC22 - SDP Link creation in CBA CCN
A15: 59430 | B15: BSS - EC20 - EC PCS SDP Low Level Design Document
A16: 79855 | B16: BSS - EC - MOP Containerized EC ansible Health Check Script - cSDP,cAIR,cAF
A17: 73431 | B17: MOP - EC-NMT5.1 ICP22-06 Installation
A18: 52660 | B18: BSS - EC - SDP - AIR Bulk Integration Solution - LLD
A19: 72227 | B19: BSS -EC22.4-cCAF- Scheduled backups- MOP
A20: 74279 | B20: BSS - EC20.1 - VCAF CERTIFICATE VALDITY PERIOD UPDATE AND RE-ISSUE - MOP
A21: 80183 | B21: BSS-EC-SDP-MANUAL OFFER DUMP SCRIPT
A22: 73433 | B22: MOP - AIR4.0 R51A ICP22-06 Installation
A23: 69532 | B23: BSS Multi-node Global Estimator - Tool
A24: 55172 | B24: BSS - EC - SDP GeoRedundancy Active-Active Solution- LLD
A25: 52203 | B25: BSS - Charging system Automation framework Offering [ECAF Assets] NGVS Installation Bare Metal SNI - Tool
... A55: 78625 | B55: BSS - N365 - Asset - Cook Book - Asset List

Sheet 3 Years Trend
A1: Monetization
A2: Year | B2: Savings | C2: Billablity Hour | D2: Savings Percentage
A3: 2022 | B3: 52196 | C3: 1149593 | D3: =B3/C3
A4: 2023 | B4: 77725 | C4: 964557 | D4: =B4/C4
A5: 2024 | B5: 100456.29 | C5: 716358 | D5: 0.1447
A6: 2025 | B6: 152115 | C6: 778770 | D6: =B6/C6
X10: EB
W11: Month | X11: 2022 | Y11: 2023 | Z11: 2024
W12: Jan | X12: 280 | Z12: ='Monthly Data 2025'!H3
W13: Feb | X13: 80 | Y13: 487 | Z13: ='Monthly Data 2025'!H4
W14: Mar | X14: 270 | Z14: ='Monthly Data 2025'!H5
W15: Apr | X15: 621.5 | Z15: ='Monthly Data 2025'!H6
W16: May | X16: 251 | Y16: 40 | Z16: ='Monthly Data 2025'!H7
W17: Jun | X17: 1540 | Y17: 1004 | Z17: ='Monthly Data 2025'!H8
W18: Jul | X18: 80 | Y18: 827 | Z18: ='Monthly Data 2025'!H9
W19: Aug | X19: 90 | Z19: ='Monthly Data 2025'!H10
W20: Sep | X20: 420.6 | Y20: 11.25 | Z20: ='Monthly Data 2025'!H11
W21: Oct | X21: 35 | Y21: 248.5 | Z21: ='Monthly Data 2025'!H12
W22: Nov | X22: 0 | Y22: 218.9 | Z22: ='Monthly Data 2025'!H13
W23: Dec | X23: 383.11 | Y23: 980.5 | Z23: ='Monthly Data 2025'!H14
W24: Grand Total | X24: =SUM(X12:X23) | Y24: =SUM(Y12:Y23) | Z24: =SUM(Z12:Z23) | AA24: =Z24-Y24
AA25: =AA24/Y24

Sheet Charts 2026

Sheet Charts 2025

Sheet Data (2)
C1: Billing | E1: Charging | G1: Overall
B2: Month | C2: Total Savings - Billing | D2: Billing Savings % | E2: Total Savings - Charging | F2: Charging Savings % | G2: Total Savings - Monetization | H2: Monetization Savings %
B3: Jan | C3: =Table2[[#This Row],[Total Savings - Billing]] | D3: =Table2[[#This Row],[Billing Savings %]] | E3: =Table2[[#This Row],[Total Savings - Charging]] | F3: =Table2[[#This Row],[Charging Savings]] | G3: =Table2[[#This Row],[Total Savings - Monetization]] | H3: =Table2[[#This Row],[Monetization Savings %]]
B4: Feb | C4: =Table2[[#This Row],[Total Savings - Billing]] | D4: =Table2[[#This Row],[Billing Savings %]] | E4: =Table2[[#This Row],[Total Savings - Charging]] | F4: =Table2[[#This Row],[Charging Savings]] | G4: =Table2[[#This Row],[Total Savings - Monetization]] | H4: =Table2[[#This Row],[Monetization Savings %]]
B5: Mar
B6: April
B7: May
B8: Jun
B9: Jul
B10: Aug
B11: Sep
B12: Oct
B13: Nov
B14: Dec
B15: YTD | C15: =SUM(C3:C14) | D15: =Table2[[#This Row],[Billing Savings %]] | E15: =SUM(E3:E14) | F15: =Table2[[#This Row],[Charging Savings]] | G15: =SUM(G3:G14) | H15: =Table2[[#This Row],[Monetization Savings %]]
B32: Asset Reuse (Hrs) -SDU
B33: Month / Year | C33: 2023 | D33: 2024
B34: Jan | C34: 0 | D34: 147.02
B35: Feb | C35: 247 | D35: 202.8
B36: Mar | C36: 0 | D36: 52
B37: Apr | C37: 0 | D37: 1202.5
B38: May | C38: 40 | D38: 910.32
B39: Jun | C39: 890 | D39: 725
B40: Jul | C40: 827 | D40: =C9
B41: Aug | C41: 0 | D41: =C10
B42: Sep | C42: 11.25 | D42: =C11
B43: Oct | O43: 248.5
B44: Nov | O44: 218.9
B45: Dec | O45: 980.5
B46: Total | C46: =SUM(C34:C45) | D46: =SUM(D34:D45) | E46: =D46-C46
D47: =E46/C46

Sheet EB Downloads
A1: Download Year | B1: Download Count
B2: ALL Assets | C2: SDU Assets | D2: Average
A3: 2023 | B3: =B21 | C3: =C21 | D3: =B3/12
A4: 2024 | B4: =D21 | C4: =E21 | D4: =B4/COUNT(D9:D20)
A7: Month | B7: 2023 | D7: 2024
B8: ALL Assets | C8: SDU Assets | D8: ALL Assets | E8: SDU Assets
A9: Jan | B9: 19 | C9: 17 | D9: 42 | E9: 27
A10: Feb | B10: 34 | C10: 23 | D10: 25 | E10: 8
A11: Mar | B11: 24 | C11: 21 | D11: 16 | E11: 12
A12: Apr | B12: 19 | C12: 11 | D12: 17 | E12: 11
A13: May | B13: 24 | C13: 13 | D13: 27 | E13: 19
A14: Jun | B14: 32 | C14: 26 | D14: 22 | E14: 20
A15: Jul | B15: 17 | C15: 5 | D15: 17 | E15: 10
A16: Aug | B16: 9 | C16: 5 | D16: 23 | E16: 20
A17: Sep | B17: 21 | C17: 10 | D17: 30 | E17: 22
A18: Oct | B18: 16 | C18: 7
A19: Nov | B19: 24 | C19: 5
A20: Dec | B20: 28 | C20: 13
A21: Totals | B21: =SUM(B9:B20) | C21: =SUM(C9:C20) | D21: =SUM(D9:D20) | E21: =SUM(E9:E20)

Sheet StarAwards 2025
A1: Month | B1: Domain | C1: Name | D1: LM
A2: Jan | B2: EC | C2: Akash Ghosh | D2: Biswajit Pahari
A3: Jan | B3: EC | C3: P. Arun Pandiyan | D3: Ramakrishnan Shanmugam
A4: Jan | B4: EC | C4: Subhajyoti Sarkar | D4: Amrit Das D
A5: Jan | B5: EC | C5: A S Balasubramanian | D5: Siva Ramakrishnan
A6: Jan | B6: EC | C6: R Rajkiran | D6: Nagarajan Vedaraman
A7: Jan | B7: EB | C7: Thota Arun Kumar | D7: Smita Behera
A8: Jan | B8: EB | C8: Dharanidhar Sahoo | D8: Nanditha Keshavamurthy
A9: Jan | B9: EB | C9: Rajni Priyanka Toppo | D9: Suman Chakraborty
A10: Feb | B10: EC | C10: Nikhil Verma | D10: Subhas Chandra Guria C
A11: Feb | B11: EC | C11: Vivek R | D11: Siva Ramakrishnan
A12: Feb | B12: EC | C12: Giridhar G | D12: Siva Ramakrishnan
... A71: Aug | B71: EB | C71: Yogesh Kumar Sahu | D71: Shishir Deshpande
